Workbook

Sheet 手打ち入力
B1: 横浜市栄区上郷町 | D1: 横浜市栄区上郷町 | F1: 横浜市栄区上郷町 | H1: 横浜市栄区上郷町 | J1: 横浜市栄区上郷町 | L1: 横浜市栄区上郷町 | N1: 横浜市栄区上郷町
B2: [JPN:Kanagawa-pref.] | D2: [JPN:Kanagawa-pref.] | F2: [JPN:Kanagawa-pref.] | H2: [JPN:Kanagawa-pref.] | J2: [JPN:Kanagawa-pref.] | L2: [JPN:Kanagawa-pref.] | N2: [JPN:Kanagawa-pref.]
B3: Segami_shiminnomori, honshu, Is., | D3: Segami_shiminnomori, honshu, Is., | F3: Segami_shiminnomori, honshu, Is., | H3: Segami_shiminnomori, honshu, Is., | J3: Segami_shiminnomori, honshu, Is., | L3: Segami_shiminnomori, honshu, Is., | N3: Segami_shiminnomori, honshu, Is.,
B4: kamigo-cho, (alt.64m) | D4: kamigo-cho, (alt.64m) | F4: kamigo-cho, (alt.64m) | H4: kamigo-cho, (alt.64m) | J4: kamigo-cho, (alt.64m) | L4: kamigo-cho, (alt.64m) | N4: kamigo-cho, (alt.64m)
B5: 7.ⅲ.2025 LK | D5: 7.ⅲ.2025 LK | F5: 7.ⅲ.2025 LK | H5: 7.ⅲ.2025 LK | J5: 7.ⅲ.2025 LK | L5: 7.ⅲ.2025 LK | N5: 7.ⅲ.2025 LK
B6: Rena Kaneko leg. | D6: Rena Kaneko leg. | F6: Rena Kaneko leg. | H6: Rena Kaneko leg. | J6: Rena Kaneko leg. | L6: Rena Kaneko leg. | N6: Rena Kaneko leg.
B7: N35.36329, E139.58276 | D7: N35.36329, E139.58276 | F7: N35.36329, E139.58276 | H7: N35.36329, E139.58276 | J7: N35.36329, E139.58276 | L7: N35.36329, E139.58276 | N7: N35.36329, E139.58276
B9: 八王子市高尾町 | D9: 八王子市高尾町 | F9: 八王子市高尾町 | H9: 八王子市高尾町 | J9: 八王子市高尾町 | L9: 八王子市高尾町 | N9: 八王子市高尾町
B10: [JPN:Tokyo-pref.] | D10: [JPN:Tokyo-pref.] | F10: [JPN:Tokyo-pref.] | H10: [JPN:Tokyo-pref.] | J10: [JPN:Tokyo-pref.] | L10: [JPN:Tokyo-pref.] | N10: [JPN:Tokyo-pref.]
B11: Takao, honshu, Is., | D11: Takao, honshu, Is., | F11: Takao, honshu, Is., | H11: Takao, honshu, Is., | J11: Takao, honshu, Is., | L11: Takao, honshu, Is., | N11: Takao, honshu, Is.,
B12: Takao-cho, (alt.424m) | D12: Takao-cho, (alt.424m) | F12: Takao-cho, (alt.424m) | H12: Takao-cho, (alt.424m) | J12: Takao-cho, (alt.424m) | L12: Takao-cho, (alt.424m) | N12: Takao-cho, (alt.424m)
B13: 25.ⅳ.2025 LK | D13: 25.ⅳ.2025 LK | F13: 25.ⅳ.2025 LK | H13: 25.ⅳ.2025 LK | J13: 25.ⅳ.2025 LK | L13: 25.ⅳ.2025 LK | N13: 25.ⅳ.2025 LK
... B199: N23.47808, E120.71771 | D199: N23.47808, E120.71771 | F199: N23.47808, E120.71771 | H199: N23.47808, E120.71771 | J199: N23.47808, E120.71771 | L199: N23.47808, E120.71771 | N199: N23.47808, E120.71771

Sheet 自動入力ラベル
B1: =入力用シート!$C$2 -> 東京都八王子市 | D1: 山梨県北杜市 | F1: 山梨県北杜市 | H1: 山梨県北杜市 | J1: 山梨県北杜市 | L1: 山梨県北杜市 | N1: 山梨県北杜市
B2: ="[" & 入力用シート!$D$2 & ":" & 入力用シート!$E$2 & "-pref.]" -> [JP:Tokyo-pref.] | D2: [JPN:Yamanashi-pref.] | F2: [JPN:Yamanashi-pref.] | H2: [JPN:Yamanashi-pref.] | J2: [JPN:Yamanashi-pref.] | L2: [JPN:Yamanashi-pref.] | N2: [JPN:Yamanashi-pref.]
B3: =入力用シート!F2 & ", " & 入力用シート!G2 & IF(入力用シート!H2<>"", ", " & 入力用シート!H2 & ".,", "") -> , Honshu, Is., | D3: Hokuto, Honshu , Is., | F3: Hokuto, Honshu , Is., | H3: Hokuto, Honshu , Is., | J3: Hokuto, Honshu , Is., | L3: Hokuto, Honshu , Is., | N3: Hokuto, Honshu , Is.,
B4: =入力用シート!$I$2 & "-" & 入力用シート!$J$2 & IF(入力用シート!$K$2<>"", ", (alt." & 入力用シート!$K$2 & "m)", "") -> Hachioji-shi | D4: Hokuto-shi, (alt.1545m) | F4: Hokuto-shi, (alt.1545m) | H4: Hokuto-shi, (alt.1545m) | J4: Hokuto-shi, (alt.1545m) | L4: Hokuto-shi, (alt.1545m) | N4: Hokuto-shi, (alt.1545m)
B5: =入力用シート!$N$2&"."&入力用シート!$M$2&"."&入力用シート!$L$2&" "&入力用シート!$O$2&", "&入力用シート!$P$2 -> 15.Ⅺ.2025 Looking, | D5: 22.viii.2025 light trap, Masaki Yamaguchi | F5: 22.viii.2025 light trap, Masaki Yamaguchi | H5: 22.viii.2025 light trap, Masaki Yamaguchi | J5: 22.viii.2025 light trap, Masaki Yamaguchi | L5: 22.viii.2025 light trap, Masaki Yamaguchi | N5: 22.viii.2025 light trap, Masaki Yamaguchi
B6: ="N" & TEXT(入力用シート!$R$2, "0.00000") & ", E" & TEXT(入力用シート!$S$2, "0.00000") -> N35.62969828324389, 139.24611963341107, E0.00000 | D6: N35.81724, E138.55184 | F6: N35.81724, E138.55184 | H6: N35.81724, E138.55184 | J6: N35.81724, E138.55184 | L6: N35.81724, E138.55184 | N6: N35.81724, E138.55184
B9: =入力用シート!$C$3 -> 神奈川県横須賀市 | D9: 山梨県北杜市 | F9: 山梨県北杜市 | H9: 山梨県北杜市 | J9: 山梨県北杜市 | L9: 山梨県北杜市 | N9: 山梨県北杜市
B10: ="[" & 入力用シート!$D$3 & ":" & 入力用シート!$E$3 & "-pref.]" -> [JP:Kanagawa -pref.] | D10: [JPN:Yamanashi-pref.] | F10: [JPN:Yamanashi-pref.] | H10: [JPN:Yamanashi-pref.] | J10: [JPN:Yamanashi-pref.] | L10: [JPN:Yamanashi-pref.] | N10: [JPN:Yamanashi-pref.]
B11: =入力用シート!F3 & ", " & 入力用シート!G3 & IF(入力用シート!H3<>"", ", " & 入力用シート!H3 & ".,", "") -> Kannonnzaki, Honshu, Is., | D11: Hokuto, Honshu , Is., | F11: Hokuto, Honshu , Is., | H11: Hokuto, Honshu , Is., | J11: Hokuto, Honshu , Is., | L11: Hokuto, Honshu , Is., | N11: Hokuto, Honshu , Is.,
B12: =入力用シート!$I$3 & "-" & 入力用シート!$J$3 & IF(入力用シート!$K$3<>"", ", (alt." & 入力用シート!$K$3 & "m)", "") -> Yokosuka-shi | D12: Hokuto-shi, (alt.1545m) | F12: Hokuto-shi, (alt.1545m) | H12: Hokuto-shi, (alt.1545m) | J12: Hokuto-shi, (alt.1545m) | L12: Hokuto-shi, (alt.1545m) | N12: Hokuto-shi, (alt.1545m)
B13: =入力用シート!$N$3&"."&入力用シート!$M$3&"."&入力用シート!$L$3&" "&入力用シート!$O$3&", "&入力用シート!$P$3 -> 9.vi.2025 Looking, M.yamaguchi | D13: 22.viii.2025 light trap, Masaki Yamaguchi | F13: 22.viii.2025 light trap, Masaki Yamaguchi | H13: 22.viii.2025 light trap, Masaki Yamaguchi | J13: 22.viii.2025 light trap, Masaki Yamaguchi | L13: 22.viii.2025 light trap, Masaki Yamaguchi | N13: 22.viii.2025 light trap, Masaki Yamaguchi
B14: ="N" & TEXT(入力用シート!$R$3, "0.00000") & ", E" & TEXT(入力用シート!$S$3, "0.00000") -> N35.25692418844977, 139.74039243964077, E0.00000 | D14: N35.81724, E138.55184 | F14: N35.81724, E138.55184 | H14: N35.81724, E138.55184 | J14: N35.81724, E138.55184 | L14: N35.81724, E138.55184 | N14: N35.81724, E138.55184
B17: =入力用シート!$C$4 -> 0 | D17: 山梨県北杜市 | F17: 山梨県北杜市 | H17: 山梨県北杜市 | J17: 山梨県北杜市 | L17: 山梨県北杜市 | N17: 山梨県北杜市
B18: ="[" & 入力用シート!$D$4 & ":" & 入力用シート!$E$4 & "-pref.]" -> [JP:-pref.] | D18: [JPN:Yamanashi-pref.] | F18: [JPN:Yamanashi-pref.] | H18: [JPN:Yamanashi-pref.] | J18: [JPN:Yamanashi-pref.] | L18: [JPN:Yamanashi-pref.] | N18: [JPN:Yamanashi-pref.]
B19: =入力用シート!F4 & ", " & 入力用シート!G4 & IF(入力用シート!H4<>"", ", " & 入力用シート!H4 & ".,", "") -> , | D19: Hokuto, Honshu , Is., | F19: Hokuto, Honshu , Is., | H19: Hokuto, Honshu , Is., | J19: Hokuto, Honshu , Is., | L19: Hokuto, Honshu , Is., | N19: Hokuto, Honshu , Is.,
B20: =入力用シート!$I$4 & "-" & 入力用シート!$J$4 & IF(入力用シート!$K$4<>"", ", (alt." & 入力用シート!$K$4 & "m)", "") -> - | D20: Hokuto-shi, (alt.1545m) | F20: Hokuto-shi, (alt.1545m) | H20: Hokuto-shi, (alt.1545m) | J20: Hokuto-shi, (alt.1545m) | L20: Hokuto-shi, (alt.1545m) | N20: Hokuto-shi, (alt.1545m)
B21: =入力用シート!$N$4&"."&入力用シート!$M$4&"."&入力用シート!$L$4&" "&入力用シート!$O$4&", "&入力用シート!$P$4 -> 15.x.2025 Looking, M.yamaguchi | D21: 22.viii.2025 light trap, Hayate Endo | F21: 22.viii.2025 light trap, Hayate Endo | H21: 22.viii.2025 light trap, Hayate Endo | J21: 22.viii.2025 light trap, Hayate Endo | L21: 22.viii.2025 light trap, Hayate Endo | N21: 22.viii.2025 light trap, Hayate Endo
B22: ="N" & TEXT(入力用シート!$R$4, "0.00000") & ", E" & TEXT(入力用シート!$S$4, "0.00000") -> N24.477538153354185, 124.23073065065063, E0.00000 | D22: N35.81724, E138.55184 | F22: N35.81724, E138.55184 | H22: N35.81724, E138.55184 | J22: N35.81724, E138.55184 | L22: N35.81724, E138.55184 | N22: N35.81724, E138.55184
B25: =入力用シート!$C$5 -> 0 | D25: 長野県上田市菅平高原 | F25: 長野県上田市菅平高原 | H25: 長野県上田市菅平高原 | J25: 長野県上田市菅平高原 | L25: 長野県上田市菅平高原 | N25: 長野県上田市菅平高原
B26: ="[" & 入力用シート!$D$5 & ":" & 入力用シート!$E$5 & "-pref.]" -> [JP:-pref.] | D26: [JPN:Nagano-pref.] | F26: [JPN:Nagano-pref.] | H26: [JPN:Nagano-pref.] | J26: [JPN:Nagano-pref.] | L26: [JPN:Nagano-pref.] | N26: [JPN:Nagano-pref.]
B27: =入力用シート!F5 & ", " & 入力用シート!G5 & IF(入力用シート!H5<>"", ", " & 入力用シート!H5 & ".,", "") -> , | D27: Sugadairakōgen, Honshu , Is., | F27: Sugadairakōgen, Honshu , Is., | H27: Sugadairakōgen, Honshu , Is., | J27: Sugadairakōgen, Honshu , Is., | L27: Sugadairakōgen, Honshu , Is., | N27: Sugadairakōgen, Honshu , Is.,
B28: =入力用シート!$I$5 & "-" & 入力用シート!$J$5 & IF(入力用シート!$K$5<>"", ", (alt." & 入力用シート!$K$5 & "m)", "") -> - | D28: Ueda-shi, (alt.1319m) | F28: Ueda-shi, (alt.1319m) | H28: Ueda-shi, (alt.1319m) | J28: Ueda-shi, (alt.1319m) | L28: Ueda-shi, (alt.1319m) | N28: Ueda-shi, (alt.1319m)
B29: =入力用シート!$N$5&"."&入力用シート!$M$5&"."&入力用シート!$L$5&" "&入力用シート!$O$5&", "&入力用シート!$P$5 -> 7.v.2025 Looking, M.yamaguchi | D29: 9.v.2025 looking, Masaki Yamaguchi | F29: 9.v.2025 looking, Masaki Yamaguchi | H29: 9.v.2025 looking, Masaki Yamaguchi | J29: 9.v.2025 looking, Masaki Yamaguchi | L29: 9.v.2025 looking, Masaki Yamaguchi | N29: 9.v.2025 looking, Masaki Yamaguchi
B30: ="N" & TEXT(入力用シート!$R$5, "0.00000") & ", E" & TEXT(入力用シート!$S$5, "0.00000") -> N36.42921814979149, 138.41797667237086, E0.00000 | D30: N36.52452, E138.34706 | F30: N36.52452, E138.34706 | H30: N36.52452, E138.34706 | J30: N36.52452, E138.34706 | L30: N36.52452, E138.34706 | N30: N36.52452, E138.34706
B33: =入力用シート!$C$6 -> 0 | D33: 長野県東御市新張 | F33: 長野県東御市新張 | H33: 長野県東御市新張 | J33: 長野県東御市新張 | L33: 長野県東御市新張 | N33: 長野県東御市新張
B34: ="[" & 入力用シート!$D$6 & ":" & 入力用シート!$E$6 & "-pref.]" -> [JP:-pref.] | D34: [JPN:Nagano-pref.] | F34: [JPN:Nagano-pref.] | H34: [JPN:Nagano-pref.] | J34: [JPN:Nagano-pref.] | L34: [JPN:Nagano-pref.] | N34: [JPN:Nagano-pref.]
B35: =入力用シート!F6 & ", " & 入力用シート!G6 & IF(入力用シート!H6<>"", ", " & 入力用シート!H6 & ".,", "") -> , | D35: Mihari, Honshu , Is., | F35: Mihari, Honshu , Is., | H35: Mihari, Honshu , Is., | J35: Mihari, Honshu , Is., | L35: Mihari, Honshu , Is., | N35: Mihari, Honshu , Is.,
B36: =入力用シート!$I$6 & "-" & 入力用シート!$J$6 & IF(入力用シート!$K$6<>"", ", (alt." & 入力用シート!$K$6 & "m)", "") -> - | D36: Tomi-shi, (alt.1730m) | F36: Tomi-shi, (alt.1730m) | H36: Tomi-shi, (alt.1730m) | J36: Tomi-shi, (alt.1730m) | L36: Tomi-shi, (alt.1730m) | N36: Tomi-shi, (alt.1730m)
B37: =入力用シート!$N$6&"."&入力用シート!$M$6&"."&入力用シート!$L$6&" "&入力用シート!$O$6&", "&入力用シート!$P$6 -> 10.v.2023 Looking, M.yamaguchi | D37: 7.v.2025 looking, Masaki Yamaguchi | F37: 7.v.2025 looking, Masaki Yamaguchi | H37: 7.v.2025 looking, Masaki Yamaguchi | J37: 7.v.2025 looking, Masaki Yamaguchi | L37: 7.v.2025 looking, Masaki Yamaguchi | N37: 7.v.2025 looking, Masaki Yamaguchi
B38: ="N" & TEXT(入力用シート!$R$6, "0.00000") & ", E" & TEXT(入力用シート!$S$6, "0.00000") -> N36.42921814979149, 138.41797667237086, E0.00000 | D38: N36.42763, E138.41967 | F38: N36.42763, E138.41967 | H38: N36.42763, E138.41967 | J38: N36.42763, E138.41967 | L38: N36.42763, E138.41967 | N38: N36.42763, E138.41967
B41: =入力用シート!$C$7 -> 0 | D41: 東京都八王子市高尾町 | F41: 東京都八王子市高尾町 | H41: 東京都八王子市高尾町 | J41: 東京都八王子市高尾町 | L41: 東京都八王子市高尾町 | N41: 東京都八王子市高尾町
B42: ="[" & 入力用シート!$D$7 & ":" & 入力用シート!$E$7 & "-pref.]" -> [JP:-pref.] | D42: [JPN:Tokyo-pref.] | F42: [JPN:Tokyo-pref.] | H42: [JPN:Tokyo-pref.] | J42: [JPN:Tokyo-pref.] | L42: [JPN:Tokyo-pref.] | N42: [JPN:Tokyo-pref.]
B43: =入力用シート!F7 & ", " & 入力用シート!G7 & IF(入力用シート!H7<>"", ", " & 入力用シート!H7 & ".,", "") -> , | D43: Takaomachi, Honshu , Is., | F43: Takaomachi, Honshu , Is., | H43: Takaomachi, Honshu , Is., | J43: Takaomachi, Honshu , Is., | L43: Takaomachi, Honshu , Is., | N43: Takaomachi, Honshu , Is.,
B44: =入力用シート!$I$7 & "-" & 入力用シート!$J$7 & IF(入力用シート!$K$7<>"", ", (alt." & 入力用シート!$K$7 & "m)", "") -> - | D44: Hachioji-shi, (alt.457m) | F44: Hachioji-shi, (alt.457m) | H44: Hachioji-shi, (alt.457m) | J44: Hachioji-shi, (alt.457m) | L44: Hachioji-shi, (alt.457m) | N44: Hachioji-shi, (alt.457m)
B45: =入力用シート!$N$7&"."&入力用シート!$M$7&"."&入力用シート!$L$7&" "&入力用シート!$O$7&", "&入力用シート!$P$7 -> 10.v.2023 Looking, M.yamaguchi | D45: 27.iv.2025 looking, Masaki Yamaguchi | F45: 27.iv.2025 looking, Masaki Yamaguchi | H45: 27.iv.2025 looking, Masaki Yamaguchi | J45: 27.iv.2025 looking, Masaki Yamaguchi | L45: 27.iv.2025 looking, Masaki Yamaguchi | N45: 27.iv.2025 looking, Masaki Yamaguchi
B46: ="N" & TEXT(入力用シート!$R$7, "0.00000") & ", E" & TEXT(入力用シート!$S$7, "0.00000") -> N36.30075052275591, 138.76238073680415, E0.00000 | D46: N35.62984, E139.25134 | F46: N35.62984, E139.25134 | H46: N35.62984, E139.25134 | J46: N35.62984, E139.25134 | L46: N35.62984, E139.25134 | N46: N35.62984, E139.25134
B49: =入力用シート!$C$8 -> 0 | D49: 山梨県上野原市西原 | F49: 山梨県上野原市西原 | H49: 山梨県上野原市西原 | J49: 山梨県上野原市西原 | L49: 山梨県上野原市西原 | N49: 山梨県上野原市西原
B50: ="[" & 入力用シート!$D$8 & ":" & 入力用シート!$E$8 & "-pref.]" -> [JP:-pref.] | D50: [JPN:Yamanashi-pref.] | F50: [JPN:Yamanashi-pref.] | H50: [JPN:Yamanashi-pref.] | J50: [JPN:Yamanashi-pref.] | L50: [JPN:Yamanashi-pref.] | N50: [JPN:Yamanashi-pref.]
B51: =入力用シート!F8 & ", " & 入力用シート!G8 & IF(入力用シート!H8<>"", ", " & 入力用シート!H8 & ".,", "") -> , | D51: Saihara, Honshu , Is., | F51: Saihara, Honshu , Is., | H51: Saihara, Honshu , Is., | J51: Saihara, Honshu , Is., | L51: Saihara, Honshu , Is., | N51: Saihara, Honshu , Is.,
B52: =入力用シート!$I$8 & "-" & 入力用シート!$J$8 & IF(入力用シート!$K$8<>"", ", (alt." & 入力用シート!$K$8 & "m)", "") -> - | D52: Uenohara-shi, (alt.525m) | F52: Uenohara-shi, (alt.525m) | H52: Uenohara-shi, (alt.525m) | J52: Uenohara-shi, (alt.525m) | L52: Uenohara-shi, (alt.525m) | N52: Uenohara-shi, (alt.525m)
...

Sheet 入力用シート
B1: 通し番号 | C1: 日本語での地点名 | D1: 国 | E1: 県名 | F1: 地点 | G1: 島名・大陸名 | H1: 島の場合Is | I1: 市区町村 | J1: 市区町村種別 | K1: alt | L1: 年 | M1: 月 | N1: 日 | O1: 採集方法 | P1: leg | Q1: 緯度経度 | R1: 緯度 | S1: 経度
B2: 1 | C2: 東京都八王子市 | D2: JP | E2: Tokyo | G2: Honshu | H2: Is | I2: Hachioji | J2: shi | L2: 2025 | M2: Ⅺ | N2: 15 | O2: Looking | Q2: 35.62969828324389, 139.24611963341107, nan | R2: 35.62969828324389, 139.24611963341107
B3: 2 | C3: 神奈川県横須賀市 | D3: JP | E3: Kanagawa | F3: Kannonnzaki | G3: Honshu | H3: Is | I3: Yokosuka | J3: shi | L3: 2025 | M3: vi | N3: 9 | O3: Looking | P3: M.yamaguchi | Q3: 35.25692418844977, 139.74039243964077, nan | R3: 35.25692418844977, 139.74039243964077
B4: 3 | D4: JP | L4: 2025 | M4: x | N4: 15 | O4: Looking | P4: M.yamaguchi | Q4: 24.477538153354185, 124.23073065065063, nan | R4: 24.477538153354185, 124.23073065065063
B5: 4 | D5: JP | L5: 2025 | M5: v | N5: 7 | O5: Looking | P5: M.yamaguchi | Q5: 36.42921814979149, 138.41797667237086, nan | R5: 36.42921814979149, 138.41797667237086
B6: 5 | D6: JP | L6: 2023 | M6: v | N6: 10 | O6: Looking | P6: M.yamaguchi | Q6: 36.42921814979149, 138.41797667237086, nan | R6: 36.42921814979149, 138.41797667237086
B7: 6 | D7: JP | L7: 2023 | M7: v | N7: 10 | O7: Looking | P7: M.yamaguchi | Q7: 36.30075052275591, 138.76238073680415, nan | R7: 36.30075052275591, 138.76238073680415
B8: 7 | D8: JP | L8: 2023 | M8: v | N8: 13 | O8: Looking | P8: M.yamaguchi | Q8: 35.85966576505269, 138.56990528469996, nan | R8: 35.85966576505269, 138.56990528469996
B9: 8 | D9: JP | L9: 2024 | M9: iv | N9: 12 | O9: Looking | P9: M.yamaguchi | Q9: 35.87618344836389, 138.57843383059884, nan | R9: 35.87618344836389, 138.57843383059884
B10: 9 | D10: JP | L10: 2025 | M10: v | N10: 30 | O10: Looking | P10: M.yamaguchi | Q10: 35.678580002441805, 139.75390978426358, nan | R10: 35.678580002441805, 139.75390978426358
B11: 10 | D11: JP | L11: 2024 | M11: v | N11: 5 | O11: Looking | P11: M.yamaguchi | Q11: 43.89158915225782, 142.45833211063322, nan | R11: 43.89158915225782, 142.45833211063322
B12: 11 | D12: JP | L12: 2024 | M12: viii | N12: 28 | O12: Looking | P12: M.yamaguchi | Q12: 35.64147570947369, 138.80963461057075, nan | R12: 35.64147570947369, 138.80963461057075
B13: 12 | D13: JP | L13: 2025 | M13: iv | N13: 19 | O13: Loioking | P13: K.harada | Q13: 34.73127914013429, 139.3922700951225, nan | R13: 34.73127914013429, 139.3922700951225
B14: 13
B15: 14
B16: 15
B17: 16
B18: 17

Sheet Sheet1
